Workbook
Name Slicer_Scheme_Name: #N/A
Name Slicer_Tháng: #N/A

Sheet CRM ANALYSIS
A1: Segmentation | B1: Total no. of clients | C1: Total Sales | D1: Total No. of Transactions | E1: Total Items Sold | F1: Transactions with >2 items | G1: ATV (Average transaction value) | H1: UPT (Unit per transaction) | J1: Create Chart for presentation
F2: 1 receipt/ transaction có từ 2 items trở lên | G2: = Total Sales / Total No. of Transactions (C/D) | H2: =Total items/ transaction (E/D)
A3: Total | B3: =SUBTOTAL(9,B4:B13) -> 337 | C3: =SUBTOTAL(9,C4:C13) -> 1492764 | D3: =SUBTOTAL(9,D4:D13) -> 386 | E3: =SUBTOTAL(9,E4:E13) -> 483 | F3: =SUBTOTAL(9,F4:F13) -> 92 | G3: =C3/D3 -> 3867.2642 | H3: =E3/D3 -> 1.2512953
A4: PLATINUM | B4: =COUNTIFS('Data pivot'!$B:$B,">'pivot'!E650000") -> 1 | C4: =SUMIFS('Data pivot'!$B:$B,'Data pivot'!$B:$B,">50000") -> 338597.29 | D4: =COUNTIFS('Data pivot'!$G:$G,">50000") -> 3 | E4: =SUMIFS('Data pivot'!$J:$J,'Data pivot'!$K:$K,">50000") -> 3 | F4: =COUNTIFS('Data pivot'!$O:$O,">50000") -> 1 | G4: =C4/D4 -> 112865.76 | H4: =E4/D4 -> 1
A5: (>$50K) | H5: =E5/D5 -> #DIV/0!
A6: GOLD | B6: =COUNTIFS('Data pivot'!$B:$B,">25000",'Data pivot'!$B:$B,"<50000") -> 5 | C6: =SUMIFS('Data pivot'!$B:$B,'Data pivot'!$B:$B,"<50000",'Data pivot'!$B:$B,">25000") -> 139090.5 | D6: =COUNTIFS('Data pivot'!$G:$G,">25000",'Data pivot'!$G:$G,"<50000") -> 5 | E6: =SUMIFS('Data pivot'!$J:$J,'Data pivot'!$K:$K,">25000",'Data pivot'!$K:$K,"<50000") -> 3 | F6: =COUNTIFS('Data pivot'!$O:$O,">25000",'Data pivot'!$O:$O,"<50000") -> 2 | G6: =C6/D6 -> 27818.099 | H6: =E6/D6 -> 0.6
A7: ($25K - <$50K) | H7: =E7/D7 -> #DIV/0!
A8: SILVER | B8: =COUNTIFS('Data pivot'!$B:$B,">10000",'Data pivot'!$B:$B,"<25000") -> 21 | C8: =SUMIFS('Data pivot'!$B:$B,'Data pivot'!$B:$B,">10000",'Data pivot'!$B:$B,"<25000") -> 318486.56 | D8: =COUNTIFS('Data pivot'!$G:$G,">10000",'Data pivot'!$G:$G,"<25000") -> 16 | E8: =SUMIFS('Data pivot'!$J:$J,'Data pivot'!$K:$K,">10000",'Data pivot'!$K:$K,"<25000") -> 36 | F8: =COUNTIFS('Data pivot'!$O:$O,">10000",'Data pivot'!$O:$O,"<25000") -> 4 | G8: =C8/D8 -> 19905.41 | H8: =E8/D8 -> 2.25
A9: ($10K – <$25K) | H9: =E9/D9 -> #DIV/0!
A10: CLIENTELING or CT | B10: =COUNTIFS('Data pivot'!$B:$B,">3000",'Data pivot'!$B:$B,"<10000") -> 84 | C10: =SUMIFS('Data pivot'!$B:$B,'Data pivot'!$B:$B,">3000",'Data pivot'!$B:$B,"<10000") -> 452548.29 | D10: =COUNTIFS('Data pivot'!$G:$G,">3000",'Data pivot'!$G:$G,"<10000") -> 97 | E10: =SUMIFS('Data pivot'!$J:$J,'Data pivot'!$K:$K,">3000",'Data pivot'!$K:$K,"<10000") -> 128 | F10: =COUNTIFS('Data pivot'!$O:$O,">3000",'Data pivot'!$O:$O,"<10000") -> 57 | G10: =C10/D10 -> 4665.4463 | H10: =E10/D10 -> 1.3195876
A11: ($3K - <$10K) | H11: =E11/D11 -> #DIV/0!
A12: OTHERS | B12: =COUNTIFS('Data pivot'!$B:$B,"<3000") -> 226 | C12: =SUMIFS('Data pivot'!$B:$B,'Data pivot'!$B:$B,"<3000") -> 244041.35 | D12: =COUNTIFS('Data pivot'!$G:$G,"<3000") -> 265 | E12: =SUMIFS('Data pivot'!$J:$J,'Data pivot'!$K:$K,"<3000") -> 313 | F12: =COUNTIFS('Data pivot'!$O:$O,"<3000") -> 28 | G12: =C12/D12 -> 920.91077 | H12: =E12/D12 -> 1.1811321
A13: (Spend threshold < $3K) | H13: =E13/D13 -> #DIV/0!
A15: Questions:
A16: Top 10 Member Account Code: | B16: 1. By Sales Quantity | D16: sheet pivot
B17: 2. By Sales Amount
A18: Analyze by Scheme Name | B18: 1. By Sales Quantity
B19: 2. By Sales Amount
A20: Top 10 Items sold
A22: Note:
A23: 1. Không được dời vị trí các cột
A24: 2. Các trường thông tin khai thác được càng nhiều càng tốt
A25: 3. Nếu sử dụng công thức thì để nguyên công thức/ Nếu sử dụng pivot thì để nguyên pivot
A26: 4. Đưa ra insights từ các metrics khai thác được
A27: Dựa vào:
A28: TOP 10 Qty by member account code --> KH 05002597 có số lượng mua nhiều nhất
A29: TOP 10 Qty by item sold --> item 18R T SMILE SM PDT16 18-35189432 là sp có số lượng bán chạy nhất (Trend or Giá cả tốt or chương trình km)
A30: TOP 10 Amt by item sold --> PT RD DI 2 65 D VVS1-70168111 là sp mang lại doanh thu cao nhất
A31: TOP 10 Amt by member account code --> 23000715 là KH mang lại doanh thu cao nhất
A32: Biểu đồ Sales Amount by Scheme name --> PLATINUM có Sales Amt lớn nhất
A33: Biểu đồ Sales Amount by Month --> Tháng 12 có Sales Amt cao nhất ( Tháng cuối năm), 3 tháng cuối năm có sales amount vượt trôi so với các tháng còn lại --> focus vào những tháng đó

Sheet Sales by scheme
A3: Nhãn Hàng | B3: Sum of Sales Amt
A4: MEMBER | B4: 557747000
A5: Tổng Cuối | B5: 557747000

Sheet sales by month
A3: Nhãn Hàng | B3: Sum of Sales Amt
A4: Tháng 6 | B4: 557747000
A5: Tổng Cuối | B5: 557747000

Sheet Raw data
A1: Date | B1: Scheme Name | C1: Store Name | D1: Item Name | E1: Member Account Code | F1: Invoice | G1: Sales Qty | H1: Sales Amt | I1: Tháng | J1: Sales amt $ | K1: Segmentation | L1: Total client | M1: tỷ giá đô
A2: 44328 | B2: PLATINUM | C2: TIFFANY - TTP | D2: SS RED RTTMN2HRTPDT1618IN-63520594 | E2: 60080458 | F2: 000000P105000000002 | G2: 1 | H2: 5416000 | I2: ="Tháng"&" "&MONTH(Du_Lieu[[#This Row],[Date]]) -> Tháng 5 | J2: =H2/$M$2 -> 231.84932 | K2: =IF(J2>50000,"PLATINUM",IF(AND(J2>25000,J2<50000),"GOLD",IF(AND(J2>10000,J2<25000),"SILVER",IF(AND(J2>3000,J2<10000),"CLIENTELING OR CT","OTHER")))) -> OTHER | L2: =1/COUNTIF(E:E,E2) -> 1 | M2: 23360 | N2: =COUNTIF(F:F,Du_Lieu[[#This Row],[Invoice]]) -> 1
A3: 44328 | B3: PLATINUM | C3: TIFFANY - TTP | D3: 18R DI XMN HRT PDT-61101195 | E3: 60082960 | F3: 000000P105000000003 | G3: 1 | H3: 38813000 | I3: ="Tháng"&" "&MONTH(Du_Lieu[[#This Row],[Date]]) -> Tháng 5 | J3: =H3/$M$2 -> 1661.5154 | K3: =IF(J3>50000,"PLATINUM",IF(AND(J3>25000,J3<50000),"GOLD",IF(AND(J3>10000,J3<25000),"SILVER",IF(AND(J3>3000,J3<10000),"CLIENTELING OR CT","OTHER")))) -> OTHER | L3: =1/COUNTIF(E:E,E3) -> 0.5 | N3: =COUNTIF(F:F,Du_Lieu[[#This Row],[Invoice]]) -> 2
A4: 44328 | B4: PLATINUM | C4: TIFFANY - TTP | D4: SS MN RTT HRT4MM BD BLTSM-27631886 | E4: 60082960 | F4: 000000P105000000003 | G4: 1 | H4: 6229000 | I4: ="Tháng"&" "&MONTH(Du_Lieu[[#This Row],[Date]]) -> Tháng 5 | J4: =H4/$M$2 -> 266.6524 | K4: =IF(J4>50000,"PLATINUM",IF(AND(J4>25000,J4<50000),"GOLD",IF(AND(J4>10000,J4<25000),"SILVER",IF(AND(J4>3000,J4<10000),"CLIENTELING OR CT","OTHER")))) -> OTHER | L4: =1/COUNTIF(E:E,E4) -> 0.5 | N4: =COUNTIF(F:F,Du_Lieu[[#This Row],[Invoice]]) -> 2
A5: 44328 | B5: PLATINUM | C5: TIFFANY - TTP | D5: 18R DI LVGHRT WIRE BLT SM-60963673 | E5: 27001049 | F5: 000000P105000000004 | G5: 1 | H5: 46937000 | I5: ="Tháng"&" "&MONTH(Du_Lieu[[#This Row],[Date]]) -> Tháng 5 | J5: =H5/$M$2 -> 2009.2894 | K5: =IF(J5>50000,"PLATINUM",IF(AND(J5>25000,J5<50000),"GOLD",IF(AND(J5>10000,J5<25000),"SILVER",IF(AND(J5>3000,J5<10000),"CLIENTELING OR CT","OTHER")))) -> OTHER | L5: =1/COUNTIF(E:E,E5) -> 1 | N5: =COUNTIF(F:F,Du_Lieu[[#This Row],[Invoice]]) -> 1
A6: 44328 | B6: MEMBER | C6: TIFFANY - TTP | D6: 18R T TRUE NRW RG 5 5-63065226 | E6: 60083471 | F6: 000000P105000000005 | G6: 1 | H6: 28884000 | I6: ="Tháng"&" "&MONTH(Du_Lieu[[#This Row],[Date]]) -> Tháng 5 | J6: =H6/$M$2 -> 1236.4726 | K6: =IF(J6>50000,"PLATINUM",IF(AND(J6>25000,J6<50000),"GOLD",IF(AND(J6>10000,J6<25000),"SILVER",IF(AND(J6>3000,J6<10000),"CLIENTELING OR CT","OTHER")))) -> OTHER | L6: =1/COUNTIF(E:E,E6) -> 0.5 | N6: =COUNTIF(F:F,Du_Lieu[[#This Row],[Invoice]]) -> 2
A7: 44328 | B7: MEMBER | C7: TIFFANY - TTP | D7: 18R T TRUE NRW RG 7-63065285 | E7: 60083471 | F7: 000000P105000000005 | G7: 1 | H7: 28884000 | I7: ="Tháng"&" "&MONTH(Du_Lieu[[#This Row],[Date]]) -> Tháng 5 | J7: =H7/$M$2 -> 1236.4726 | K7: =IF(J7>50000,"PLATINUM",IF(AND(J7>25000,J7<50000),"GOLD",IF(AND(J7>10000,J7<25000),"SILVER",IF(AND(J7>3000,J7<10000),"CLIENTELING OR CT","OTHER")))) -> OTHER | L7: =1/COUNTIF(E:E,E7) -> 0.5 | N7: =COUNTIF(F:F,Du_Lieu[[#This Row],[Invoice]]) -> 2
A8: 44328 | B8: PLATINUM | C8: TIFFANY - TTP | D8: 18W DI T WIRE BLT MD-33263473 | E8: 60073222 | F8: 000000P105000000006 | G8: 1 | H8: 114633000 | I8: ="Tháng"&" "&MONTH(Du_Lieu[[#This Row],[Date]]) -> Tháng 5 | J8: =H8/$M$2 -> 4907.2346 | K8: =IF(J8>50000,"PLATINUM",IF(AND(J8>25000,J8<50000),"GOLD",IF(AND(J8>10000,J8<25000),"SILVER",IF(AND(J8>3000,J8<10000),"CLIENTELING OR CT","OTHER")))) -> CLIENTELING OR CT | L8: =1/COUNTIF(E:E,E8) -> 1 | N8: =COUNTIF(F:F,Du_Lieu[[#This Row],[Invoice]]) -> 1
A9: 44329 | B9: MEMBER | C9: TIFFANY - TTP | D9: SS BL MNRTTHRT 4MMBDBLTMD-26659604 | E9: 60084724 | F9: 000000P105000000008 | G9: 1 | H9: 6229000 | I9: ="Tháng"&" "&MONTH(Du_Lieu[[#This Row],[Date]]) -> Tháng 5 | J9: =H9/$M$2 -> 266.6524 | K9: =IF(J9>50000,"PLATINUM",IF(AND(J9>25000,J9<50000),"GOLD",IF(AND(J9>10000,J9<25000),"SILVER",IF(AND(J9>3000,J9<10000),"CLIENTELING OR CT","OTHER")))) -> OTHER | L9: =1/COUNTIF(E:E,E9) -> 0.5 | N9: =COUNTIF(F:F,Du_Lieu[[#This Row],[Invoice]]) -> 2
A10: 44329 | B10: MEMBER | C10: TIFFANY - TTP | D10: SS PK MNRTTHRT4MMBDBLTMD-30978811 | E10: 60084724 | F10: 000000P105000000008 | G10: 1 | H10: 6229000 | I10: ="Tháng"&" "&MONTH(Du_Lieu[[#This Row],[Date]]) -> Tháng 5 | J10: =H10/$M$2 -> 266.6524 | K10: =IF(J10>50000,"PLATINUM",IF(AND(J10>25000,J10<50000),"GOLD",IF(AND(J10>10000,J10<25000),"SILVER",IF(AND(J10>3000,J10<10000),"CLIENTELING OR CT","OTHER")))) -> OTHER | L10: =1/COUNTIF(E:E,E10) -> 0.5 | N10: =COUNTIF(F:F,Du_Lieu[[#This Row],[Invoice]]) -> 2
A11: 44332 | B11: GOLD | C11: TIFFANY - TTP | D11: SS PK MNRT HRT 4MMBDBLTSM-30978838 | E11: MA002707 | F11: 000000P105000000010 | G11: 1 | H11: 6229000 | I11: ="Tháng"&" "&MONTH(Du_Lieu[[#This Row],[Date]]) -> Tháng 5 | J11: =H11/$M$2 -> 266.6524 | K11: =IF(J11>50000,"PLATINUM",IF(AND(J11>25000,J11<50000),"GOLD",IF(AND(J11>10000,J11<25000),"SILVER",IF(AND(J11>3000,J11<10000),"CLIENTELING OR CT","OTHER")))) -> OTHER | L11: =1/COUNTIF(E:E,E11) -> 0.33333333 | N11: =COUNTIF(F:F,Du_Lieu[[#This Row],[Invoice]]) -> 1
A12: 44332 | B12: MEMBER | C12: TIFFANY - TTP | D12: SS RD RTTMNHRT 4MMBDBLTMD-61941797 | E12: 60084728 | F12: 000000P105000000011 | G12: 1 | H12: 6229000 | I12: ="Tháng"&" "&MONTH(Du_Lieu[[#This Row],[Date]]) -> Tháng 5 | J12: =H12/$M$2 -> 266.6524 | K12: =IF(J12>50000,"PLATINUM",IF(AND(J12>25000,J12<50000),"GOLD",IF(AND(J12>10000,J12<25000),"SILVER",IF(AND(J12>3000,J12<10000),"CLIENTELING OR CT","OTHER")))) -> OTHER | L12: =1/COUNTIF(E:E,E12) -> 0.25 | N12: =COUNTIF(F:F,Du_Lieu[[#This Row],[Invoice]]) -> 1
A13: 44332 | B13: GOLD | C13: TIFFANY - TTP | D13: SS PK MNRT HRT 4MMBDBLTSM-30978838 | E13: MA002707 | F13: 000000P105000000012 | G13: -1 | H13: -6229000 | I13: ="Tháng"&" "&MONTH(Du_Lieu[[#This Row],[Date]]) -> Tháng 5 | J13: =H13/$M$2 -> -266.6524 | K13: =IF(J13>50000,"PLATINUM",IF(AND(J13>25000,J13<50000),"GOLD",IF(AND(J13>10000,J13<25000),"SILVER",IF(AND(J13>3000,J13<10000),"CLIENTELING OR CT","OTHER")))) -> OTHER | L13: =1/COUNTIF(E:E,E13) -> 0.33333333 | N13: =COUNTIF(F:F,Du_Lieu[[#This Row],[Invoice]]) -> 1
A14: 44332 | B14: MEMBER | C14: TIFFANY - TTP | D14: SS RD RTTMNHRT 4MMBDBLTMD-61941797 | E14: 60084728 | F14: 000000P105000000014 | G14: -1 | H14: -6229000 | I14: ="Tháng"&" "&MONTH(Du_Lieu[[#This Row],[Date]]) -> Tháng 5 | J14: =H14/$M$2 -> -266.6524 | K14: =IF(J14>50000,"PLATINUM",IF(AND(J14>25000,J14<50000),"GOLD",IF(AND(J14>10000,J14<25000),"SILVER",IF(AND(J14>3000,J14<10000),"CLIENTELING OR CT","OTHER")))) -> OTHER | L14: =1/COUNTIF(E:E,E14) -> 0.25 | N14: =COUNTIF(F:F,Du_Lieu[[#This Row],[Invoice]]) -> 1
... A496: 44545 | B496: NEW | C496: TIFFANY - TTP | D496: SS RD RTTMNHRT 4MMBDBLTLG-61941819 | E496: MC0000001591 | F496: 000000P105000000436 | G496: 1 | H496: 6951000 | I496: ="Tháng"&" "&MONTH(Du_Lieu[[#This Row],[Date]]) -> Tháng 12 | J496: =H496/$M$2 -> 297.55993 | K496: =IF(J496>50000,"PLATINUM",IF(AND(J496>25000,J496<50000),"GOLD",IF(AND(J496>10000,J496<25000),"SILVER",IF(AND(J496>3000,J496<10000),"CLIENTELING OR CT","OTHER")))) -> OTHER | L496: =1/COUNTIF(E:E,E496) -> 1 | N496: =COUNTIF(F:F,Du_Lieu[[#This Row],[Invoice]]) -> 1

Sheet pivot
P2: TOP 10 Qty by member account code | S2: TOP 10 amt by member account code | V2: TOP 10 QTY BY ITEM SOLD | Y2: TOP 10 AMT BY ITEM SOLD | AB2: ANALYZE BY SCHEME NAME
A3: Invoice | B3: Sales Qty | C3: Sum of Sales amt $ | E3: Member Account Code | F3: Sum of Sales amt $ | H3: Item Name | I3: Sum of Sales Qty | J3: Sum of Sales amt $ | L3: Invoice | M3: Item Name | N3: Sum of Sales amt $ | P3: Member Account Code | Q3: Sum of Sales Qty | S3: Member Account Code | T3: Sum of Sales Amt | V3: Item Name | W3: Sum of Sales Qty | Y3: Item Name | Z3: Sum of Sales Amt | AB3: Scheme Name | AC3: Count of Invoice | AD3: Sum of Sales Qty | AE3: Sum of Sales Amt
A4: 000000P105000000002 | B4: 1 | C4: 231.84932 | E4: 03001727 | F4: 792.1661 | H4: 18R ATLAS X CLOSED LG HOOP ER-67786130 | I4: 1 | J4: 3554.8373 | L4: 000000P105000000002 | M4: SS RED RTTMN2HRTPDT1618IN-63520594 | N4: 231.84932 | P4: 05002597 | Q4: 10 | S4: 23000715 | T4: 4097881000 | V4: 18R T SMILE SM PDT16 18-35189432 | W4: 10 | Y4: PT RD DI 2 65 D VVS1-70168111 | Z4: 4097881000 | AB4: BOD | AC4: 3 | AD4: 3 | AE4: 1705043800
A5: 000000P105000000003 | B5: 1 | C5: 1928.1678 | E5: 04002116 | F5: 633.73288 | H5: 18R ATLS X CLSD INTRLCKPDT161-67789237 | I5: 3 | J5: 6607.4486 | L5: 000000P105000000003 | M5: 18R DI XMN HRT PDT-61101195 | N5: 1661.5154 | P5: 20002141 | Q5: 6 | S5: 60064055 | T5: 2201483000 | V5: SS BL MNRTTHRT 4MMBDBLTSM-27630146 | W5: 7 | Y5: PT RD DI 2 03 F VVS1-69252907 | Z5: 2130176000 | AB5: GOLD | AC5: 67 | AD5: 65 | AE5: 3225354000
A6: 000000P105000000004 | B6: 1 | C6: 2009.2894 | E6: 05000604 | F6: 14064.769 | H6: 18R DI .03TW T SMILE MN PDT-63843385 | I6: 3 | J6: 5216.3527 | L6: 000000P105000000003 | M6: SS MN RTT HRT4MM BD BLTSM-27631886 | N6: 266.6524 | P6: 39000072 | Q6: 5 | S6: 99000004 | T6: 1610268800 | V6: SS MN RTT HRT4MM BD BLTSM-27631886 | W6: 7 | Y6: 18Y CUDI2 24FV VVS2-63727164 | Z6: 1610268800 | AB6: MEMBER | AC6: 204 | AD6: 196 | AE6: 4487652000
A7: 000000P105000000005 | B7: 1 | C7: 2472.9452 | E7: 05001228 | F7: 1275.1284 | H7: 18R DI 13 CROWN KEY-25460979 | I7: 1 | J7: 3554.8373 | L7: 000000P105000000004 | M7: 18R DI LVGHRT WIRE BLT SM-60963673 | N7: 2009.2894 | P7: 60063589 | Q7: 4 | S7: 22000426 | T7: 732926000 | V7: SS BLMNRTTHRT4MMBD BLT XS-63686085 | W7: 6 | Y7: PT RD DI 1 31 F VS1-69029906 | Z7: 685989000 | AB7: NEW | AC7: 9 | AD7: 9 | AE7: 139821000
A8: 000000P105000000006 | B8: 1 | C8: 4907.2346 | E8: 05001353 | F8: 463.69863 | H8: 18R DI BG T SQR PDT 16 18-62996021 | I8: 2 | J8: 4714.0411 | L8: 000000P105000000005 | M8: 18R T TRUE NRW RG 5 5-63065226 | N8: 1236.4726 | P8: 60065272 | Q8: 4 | S8: 60064032 | T8: 685989000 | V8: SS MN RTT HRT 4MMBD BLTMD-23984024 | W8: 6 | Y8: PT CU DI 1 12 G VVS1-68800889 | Z8: 617390000 | AB8: PLATINUM | AC8: 206 | AD8: 204 | AE8: 25040954000
A9: 000000P105000000008 | B9: 1 | C9: 533.30479 | E9: 05001498 | F9: 7998.4161 | H9: 18R DI DBL LVG HRT ER-63062529 | I9: 1 | J9: 1352.3973 | L9: 000000P105000000005 | M9: 18R T TRUE NRW RG 7-63065285 | N9: 1236.4726 | P9: 22000031 | Q9: 4 | S9: 60084749 | T9: 617390000 | V9: 18R PENDANT CHAIN 16IN-25508327 | W9: 6 | Y9: PT RD DI 1 21 E VS2-69029752 | Z9: 602949000 | AB9: STAFF | AC9: 1 | AD9: 1 | AE9: 11554000
A10: 000000P105000000010 | B10: 1 | C10: 266.6524 | E10: 05002520 | F10: 4404.9229 | H10: 18R DI DBL LVGHRT MN PDT-63058262 | I10: 1 | J10: 1043.2791 | L10: 000000P105000000006 | M10: 18W DI T WIRE BLT MD-33263473 | N10: 4907.2346 | P10: 60085095 | Q10: 4 | S10: 08001224 | T10: 609900000 | V10: SS BL MNRTT 2HRT PDT 16IN-27125107 | W10: 6 | Y10: 18RHALFDIT1WDHNGBGLMD-67792858 | Z10: 572260000 | AB10: TEMP | AC10: 5 | AD10: 5 | AE10: 260588000
A11: 000000P105000000011 | B11: 1 | C11: 266.6524 | E11: 05002597 | F11: 14339.298 | H11: 18R DI LVGHRT WIRE BLT MD-60963703 | I11: 1 | J11: 2009.2894 | L11: 000000P105000000008 | M11: SS BL MNRTTHRT 4MMBDBLTMD-26659604 | N11: 266.6524 | P11: 13000508 | Q11: 3 | S11: MC0000001188 | T11: 602949000 | V11: 18R PENDANT CHAIN 18IN-25508335 | W11: 5 | Y11: 18RHLFDIT1NRWHNGBGLMD-68315786 | Z11: 570454000 | AB11: Grand Total | AC11: 495 | AD11: 483 | AE11: 34870966800
A12: 000000P105000000012 | B12: -1 | C12: -266.6524 | E12: 06000114 | F12: 6375.5137 | H12: 18R DI LVGHRT WIRE BLT SM-60963673 | I12: 1 | J12: 2009.2894 | L12: 000000P105000000008 | M12: SS PK MNRTTHRT4MMBDBLTMD-30978811 | N12: 266.6524 | P12: 60079850 | Q12: 3 | S12: 16000039 | T12: 505466000 | V12: 18Y T SMILE SM PDT16 18-35189459 | W12: 5 | Y12: PT RD DI 1 09 F VS1-69031420 | Z12: 505466000
A13: 000000P105000000014 | B13: -1 | C13: -266.6524 | E13: 07002811 | F13: 2357.0205 | H13: 18R DI MD ROUND VIC KEY-37688304 | I13: 1 | J13: 8577.9538 | L13: 000000P105000000010 | M13: SS PK MNRT HRT 4MMBDBLTSM-30978838 | N13: 266.6524 | P13: 60074161 | Q13: 3 | S13: 20001306 | T13: 478388000 | V13: 18W T SMILE SM PDT16 18-35189424 | W13: 4 | Y13: PT RDDI 91 G VS1-66866815 | Z13: 388126000
A14: 000000P105000000016 | B14: 1 | C14: 266.6524 | E14: 08001224 | F14: 26108.733 | H14: 18R DI MN FLEURDELIS KEY-62866993 | I14: 1 | J14: 2704.7945 | L14: 000000P105000000011 | M14: SS RD RTTMNHRT 4MMBDBLTMD-61941797 | N14: 266.6524 | P14: 22000398 | Q14: 3 | S14: Grand Total | T14: 12142640800 | V14: 18R DI T SMILE SM PDT-63058823 | W14: 4 | Y14: Grand Total | Z14: 11780959800
A15: 000000P105000000017 | B15: 1 | C15: 3632.149 | E15: 08001361 | F15: 10896.361 | H15: 18R DI MN PETALS KEY-60660190 | I15: 1 | J15: 3554.8373 | L15: 000000P105000000012 | M15: SS PK MNRT HRT 4MMBDBLTSM-30978838 | N15: -266.6524 | P15: 60084742 | Q15: 3 | V15: Grand Total | W15: 66
A16: 000000P105000000018 | B16: 1 | C16: 2704.7945 | E16: 08001406 | F16: 4211.7295 | H16: 18R DI MN TFCRCLT PDT-61691774 | I16: 1 | J16: 2163.8271 | L16: 000000P105000000014 | M16: SS RD RTTMNHRT 4MMBDBLTMD-61941797 | N16: -266.6524 | P16: 24001530 | Q16: 3
A17: 000000P105000000019 | B17: 1 | C17: 266.6524 | E17: 09000030 | F17: 583.47603 | H17: 18R DI MN VICTORIA KEY-62867019 | I17: 2 | J17: 5873.2021 | L17: 000000P105000000016 | M17: SS BL MNRTTHRT 4MMBDBLTMD-26659604 | N17: 266.6524 | P17: 60073476 | Q17: 3
A18: 000000P105000000020 | B18: 1 | C18: 266.6524 | E18: 09000109 | F18: 2163.8271 | H18: 18R DI MOP T WIRE BLT MD-64028626 | I18: 3 | J18: 11823.673 | L18: 000000P105000000017 | M18: 18R DI T WIRE RG 6 5-35007857 | N18: 2434.2894 | P18: 20001130 | Q18: 3
A19: 000000P105000000021 | B19: 1 | C19: 1120.5479 | E19: 09000224 | F19: 595.11986 | H19: 18R DI MOP T WIRE BLT SM-64028596 | I19: 3 | J19: 11823.673 | L19: 000000P105000000017 | M19: 18RDI SMRD PRCD ATL PDT16-30480554 | N19: 1197.8596 | P19: 60079623 | Q19: 3
A20: 000000P105000000022 | B20: 1 | C20: 4335.4452 | E20: 09001516 | F20: 1124.4435 | H20: 18R DI MOP T WIRE RG 4 5-64027867 | I20: 1 | J20: 2434.2894 | L20: 000000P105000000018 | M20: 18W DI TURQ T WIRE RG 5-64028103 | N20: 2704.7945 | P20: 60085066 | Q20: 3
A21: 000000P105000000023 | B21: 1 | C21: 266.6524 | E21: 09001886 | F21: 17078.682 | H21: 18R DI MOP T WIRE RG 5 5-64027905 | I21: 1 | J21: 2434.2894 | L21: 000000P105000000019 | M21: SS PK MNRT HRT 4MMBDBLTSM-30978838 | N21: 266.6524 | P21: 60079969 | Q21: 3
A22: 000000P105000000024 | B22: 1 | C22: 112.07192 | E22: 12001422 | F22: 297.55993 | H22: 18R DI MOP T WIRE RG 6 5-64027956 | I22: 1 | J22: 2434.2894 | L22: 000000P105000000020 | M22: SS RD RTTMNHRT 4MMBDBLTMD-61941797 | N22: 266.6524 | P22: MC0000000186 | Q22: 3
A23: 000000P105000000025 | B23: 1 | C23: 1738.7842 | E23: 13000017 | F23: 1159.2038 | H23: 18R DI MOP T WIRE RG 6-64027921 | I23: 1 | J23: 2434.2894 | L23: 000000P105000000021 | M23: 18R T TWO CHN DBL BLT SM-62355417 | N23: 1120.5479 | P23: 60084750 | Q23: 3
A24: 000000P105000000026 | B24: 1 | C24: 2086.5582 | E24: 13000241 | F24: 6591.9521 | H24: 18R DI MOP T WIRE RG 7 5-64027999 | I24: 1 | J24: 2434.2894 | L24: 000000P105000000022 | M24: 18R LG DI DAISY KEY-26887623 | N24: 3709.4178 | P24: 20001306 | Q24: 3
A25: 000000P105000000027 | B25: 1 | C25: 2704.8373 | E25: 13000482 | F25: 2782.0634 | H25: 18R DI MOP T WIRE RG 7-64027972 | I25: 1 | J25: 2434.2894 | L25: 000000P105000000022 | M25: 18R PENDANT CHAIN 16IN-25508327 | N25: 370.97603 | P25: 09001886 | Q25: 3
A26: 000000P105000000029 | B26: 1 | C26: 231.84932 | E26: 13000508 | F26: 7766.6096 | H26: 18R DI MOP T WIRE RG 8-64028014 | I26: 1 | J26: 2434.2894 | L26: 000000P105000000022 | M26: CLRBLK PIGGYBANK ERTHNWRE-60559961 | N26: 255.05137 | P26: 60062750 | Q26: 3
A27: 000000P105000000030 | B27: 1 | C27: 7727.9966 | E27: 13000850 | F27: 332.32021 | H27: 18R DI PV T TRUE .23TW NW RG 6.5-63961817 | I27: 1 | J27: 5177.6969 | L27: 000000P105000000023 | M27: SS MN RTT HRT4MM BD BLTSM-27631886 | N27: 266.6524 | P27: 08001224 | Q27: 3
... A30: 000000P105000000033 | B30: 1 | C30: 757.40582 | E30: 19000025 | F30: 2357.0634 | H30: 18R DI SM OPN CRCL PDT 16-60573204 | I30: 1 | J30: 4288.9983 | L30: 000000P105000000026 | M30: 18R HLFDI T1 NRWRG6 5-67795377 | N30: 2086.5582 | P30: Grand Total | Q30: 94
A31: 000000P105000000034 | B31: 1 | C31: 231.84932 | E31: 19000068 | F31: 7650.6421 | H31: 18R DI T SMILE LG PDT1618-63104981 | I31: 1 | J31: 5409.5462 | L31: 000000P105000000027 | M31: 18R DI TCO 3MM RG 6-27897908 | N31: 1506.9777
A32: 000000P105000000037 | B32: 1 | C32: 1584.2466 | E32: 20000178 | F32: 266.6524 | H32: 18R DI T SMILE SM BLT SM-36819588 | I32: 1 | J32: 3091.1815 | L32: 000000P105000000027 | M32: 18R TCO 3MM RG 7-33026617 | N32: 1197.8596
A33: 000000P105000000038 | B33: 1 | C33: 1545.5908 | E33: 20000519 | F33: 297.55993 | H33: 18R DI T SMILE SM PDT-63058823 | I33: 4 | J33: 11746.404 | L33: 000000P105000000029 | M33: SS BL MN RTT 2HRT PDT 18-30210417 | N33: 231.84932
A34: 000000P105000000039 | B34: 1 | C34: 2434.2894 | E34: 20000526 | F34: 297.55993 | H34: 18R DI T SQR WRAP RG 4 5-35606793 | I34: 1 | J34: 3323.0308 | L34: 000000P105000000030 | M34: 18R DI SM HEART KEY-62859954 | N34: 3284.375
A35: 000000P105000000040 | B35: 1 | C35: 1120.5479 | E35: 20000751 | F35: 2357.0205 | H35: 18R DI T SQR WRAP RG 6-35606696 | I35: 1 | J35: 3323.0308 | L35: 000000P105000000030 | M35: 18R PENDANT CHAIN 16IN-25508327 | N35: 370.97603
A36: 000000P105000000041 | B36: 1 | C36: 6800.5565 | E36: 20000850 | F36: 285.9589 | H36: 18R DI T WIRE BLT MD-33263538 | I36: 2 | J36: 9814.4692 | L36: 000000P105000000030 | M36: SS HW MD 19MM WRAP NL36IN-62611928 | N36: 3438.9127
A37: 000000P105000000042 | B37: 1 | C37: 231.84932 | E37: 20001130 | F37: 4837.714 | H37: 18R DI T WIRE BLT SM-35093338 | I37: 2 | J37: 9814.4692 | L37: 000000P105000000030 | M37: TTN BLK 1837 NRW RG 7 5-25923677 | N37: 316.86644
A38: 000000P105000000043 | B38: 1 | C38: 6823.8014 | E38: 20001306 | F38: 20478.938 | H38: 18R DI T WIRE FC RING 4 5-34901473 | I38: 1 | J38: 3438.9127 | L38: 000000P105000000030 | M38: TTN BLK 1837 NRW RG 7-25923669 | N38: 316.86644
A39: 000000P105000000044 | B39: 1 | C39: 2975.2997 | E39: 20002141 | F39: 14721.747 | H39: 18R DI T WIRE FC RING 6 5-34901538 | I39: 1 | J39: 3438.9127 | L39: 000000P105000000031 | M39: SS 1837 NRW BASC RG 5 5-22993763 | N39: 266.6524
A40: 000000P105000000045 | B40: 1 | C40: 3709.4178 | E40: 21000564 | F40: 3168.4503 | H40: 18R DI T WIRE RG 4 5-35008071 | I40: 1 | J40: 2434.2894 | L40: 000000P105000000032 | M40: SS 1837 NRRW CUFF MD-22992422 | N40: 494.60616
A41: 000000P105000000046 | B41: 1 | C41: 529.36644 | E41: 22000014 | F41: 266.6524 | H41: 18R DI T WIRE RG 5 5-35007903 | I41: 2 | J41: 4868.5788 | L41: 000000P105000000033 | M41: SS 1837 INTLK SM PDT 16IN-22992139 | N41: 490.75342
A42: 000000P105000000047 | B42: 1 | C42: 583.47603 | E42: 22000031 | F42: 13562.5 | H42: 18R DI T WIRE RG 5-35008144 | I42: 2 | J42: 4868.5788 | L42: 000000P105000000033 | M42: SS HPKMNRTTHRT4MMBDBLTXS-63686115 | N42: 266.6524
... A343: 000000P105000000383 | B343: 1 | C343: 2434.2894 | E343: Grand Total | F343: 1492764 | H343: Grand Total | I343: 483 | J343: 1492764 | L343: 000000P105000000286 | M343: PT DI TCO 3MM RG 5 5-23776316 | N343: 2009.2894
...

Sheet Data pivot
A1: Member Account Code | B1: Sum of Sales amt $ | E1: Invoice | F1: Sales Qty | G1: Sum of Sales amt $ | I1: Item Name | J1: Sum of Sales Qty | K1: Sum of Sales amt $ | M1: Invoice | N1: Item Name | O1: Sum of Sales amt $
A2: 03001727 | B2: 792.1661 | E2: 000000P105000000002 | F2: 1 | G2: 231.84932 | I2: 18R ATLAS X CLOSED LG HOOP ER-67786130 | J2: 1 | K2: 3554.8373 | M2: 000000P105000000003 | N2: 18R DI XMN HRT PDT-61101195 | O2: =SUMIFS('Raw data'!$J:$J,'Raw data'!$F:$F,'Data pivot'!M2) -> 1928.1678
A3: 04002116 | B3: 633.73288 | E3: 000000P105000000003 | F3: 1 | G3: 1928.1678 | I3: 18R ATLS X CLSD INTRLCKPDT161-67789237 | J3: 3 | K3: 6607.4486 | M3: 000000P105000000005 | N3: 18R T TRUE NRW RG 5 5-63065226 | O3: =SUMIFS('Raw data'!$J:$J,'Raw data'!$F:$F,'Data pivot'!M3) -> 2472.9452
A4: 05000604 | B4: 14064.769 | E4: 000000P105000000004 | F4: 1 | G4: 2009.2894 | I4: 18R DI .03TW T SMILE MN PDT-63843385 | J4: 3 | K4: 5216.3527 | M4: 000000P105000000008 | N4: SS BL MNRTTHRT 4MMBDBLTMD-26659604 | O4: =SUMIFS('Raw data'!$J:$J,'Raw data'!$F:$F,'Data pivot'!M4) -> 533.30479
A5: 05001228 | B5: 1275.1284 | E5: 000000P105000000005 | F5: 1 | G5: 2472.9452 | I5: 18R DI 13 CROWN KEY-25460979 | J5: 1 | K5: 3554.8373 | M5: 000000P105000000017 | N5: 18R DI T WIRE RG 6 5-35007857 | O5: =SUMIFS('Raw data'!$J:$J,'Raw data'!$F:$F,'Data pivot'!M5) -> 3632.149
A6: 05001353 | B6: 463.69863 | E6: 000000P105000000006 | F6: 1 | G6: 4907.2346 | I6: 18R DI BG T SQR PDT 16 18-62996021 | J6: 2 | K6: 4714.0411 | M6: 000000P105000000022 | N6: 18R LG DI DAISY KEY-26887623 | O6: =SUMIFS('Raw data'!$J:$J,'Raw data'!$F:$F,'Data pivot'!M6) -> 4335.4452
A7: 05001498 | B7: 7998.4161 | E7: 000000P105000000008 | F7: 1 | G7: 533.30479 | I7: 18R DI DBL LVG HRT ER-63062529 | J7: 1 | K7: 1352.3973 | M7: 000000P105000000027 | N7: 18R DI TCO 3MM RG 6-27897908 | O7: =SUMIFS('Raw data'!$J:$J,'Raw data'!$F:$F,'Data pivot'!M7) -> 2704.8373
A8: 05002520 | B8: 4404.9229 | E8: 000000P105000000010 | F8: 1 | G8: 266.6524 | I8: 18R DI DBL LVGHRT MN PDT-63058262 | J8: 1 | K8: 1043.2791 | M8: 000000P105000000030 | N8: 18R DI SM HEART KEY-62859954 | O8: =SUMIFS('Raw data'!$J:$J,'Raw data'!$F:$F,'Data pivot'!M8) -> 7727.9966
A9: 05002597 | B9: 14339.298 | E9: 000000P105000000011 | F9: 1 | G9: 266.6524 | I9: 18R DI LVGHRT WIRE BLT MD-60963703 | J9: 1 | K9: 2009.2894 | M9: 000000P105000000033 | N9: SS 1837 INTLK SM PDT 16IN-22992139 | O9: =SUMIFS('Raw data'!$J:$J,'Raw data'!$F:$F,'Data pivot'!M9) -> 757.40582
A10: 06000114 | B10: 6375.5137 | E10: 000000P105000000012 | F10: -1 | G10: -266.6524 | I10: 18R DI LVGHRT WIRE BLT SM-60963673 | J10: 1 | K10: 2009.2894 | M10: 000000P105000000041 | N10: 18R MOP T TWO CL ER-66886042 | O10: =SUMIFS('Raw data'!$J:$J,'Raw data'!$F:$F,'Data pivot'!M10) -> 6800.5565
A11: 07002811 | B11: 2357.0205 | E11: 000000P105000000014 | F11: -1 | G11: -266.6524 | I11: 18R DI MD ROUND VIC KEY-37688304 | J11: 1 | K11: 8577.9538 | M11: 000000P105000000043 | N11: 18R DI 13 CROWN KEY-25460979 | O11: =SUMIFS('Raw data'!$J:$J,'Raw data'!$F:$F,'Data pivot'!M11) -> 6823.8014
A12: 08001224 | B12: 26108.733 | E12: 000000P105000000016 | F12: 1 | G12: 266.6524 | I12: 18R DI MN FLEURDELIS KEY-62866993 | J12: 1 | K12: 2704.7945 | M12: 000000P105000000044 | N12: 18R DI TCO 3MM RG 6-27897908 | O12: =SUMIFS('Raw data'!$J:$J,'Raw data'!$F:$F,'Data pivot'!M12) -> 2975.2997
A13: 08001361 | B13: 10896.361 | E13: 000000P105000000017 | F13: 1 | G13: 3632.149 | I13: 18R DI MN PETALS KEY-60660190 | J13: 1 | K13: 3554.8373 | M13: 000000P105000000045 | N13: 18W DI MD ATLPRCDRG 7-35102272 | O13: =SUMIFS('Raw data'!$J:$J,'Raw data'!$F:$F,'Data pivot'!M13) -> 3709.4178
... A93: 60075010 | B93: 297.55993 | E93: 000000P105000000102 | F93: 1 | G93: 5564.1267 | I93: 18R T SQR BLT SMALL-33282354 | J93: 1 | K93: 6877.8253 | M93: 000000P105000000432 | N93: SS OLVLF NRW BD RG 7-30210611 | O93: =SUMIFS('Raw data'!$J:$J,'Raw data'!$F:$F,'Data pivot'!M93) -> 896.48973
A94: 60076597 | B94: 463.69863 | E94: 000000P105000000103 | F94: 1 | G94: 266.6524 | I94: 18R T TRUE NRW RG 5 5-63065226 | J94: 1 | K94: 1236.4726
A95: 60077273 | B95: 2434.2894 | E95: 000000P105000000104 | F95: 1 | G95: 498.50171 | I95: 18R T TRUE NRW RG 7 5-63065307 | J95: 1 | K95: 1236.4726
A96: 60077685 | B96: 11900.985 | E96: 000000P105000000105 | F96: 1 | G96: 3091.1815 | I96: 18R T TRUE NRW RG 7-63065285 | J96: 1 | K96: 1236.4726
A97: 60077793 | B97: 850.08562 | E97: 000000P105000000106 | F97: 1 | G97: 4907.2346 | I97: 18R T TRUE WD RG 7 5-63064386 | J97: 1 | K97: 2086.5582
A98: 60077796 | B98: 2588.8699 | E98: 000000P105000000107 | F98: 1 | G98: 463.69863 | I98: 18R T TRUE WD RG 7-63064351 | J98: 1 | K98: 2086.5582
A99: 60078232 | B99: 363.22774 | E99: 000000P105000000108 | F99: 1 | G99: 12016.866 | I99: 18R T TWO CHN DBL BLT SM-62355417 | J99: 1 | K99: 1120.5479
A100: 60078468 | B100: 7611.9863 | E100: 000000P105000000109 | F100: 1 | G100: 1738.7842 | I100: 18R T TWO DI NRW RG 4 5-36821469 | J100: 1 | K100: 3709.4178
A101: 60078527 | B101: 463.69863 | E101: 000000P105000000110 | F101: 1 | G101: 4343.1079 | I101: 18R T TWO DI NRW RG 6-36821329 | J101: 1 | K101: 3709.4178
A102: 60079105 | B102: 4173.0736 | E102: 000000P105000000111 | F102: 1 | G102: 266.6524 | I102: 18R T TWO DI PAVE NRW 6 5-36822325 | J102: 1 | K102: 6143.7072
A103: 60079623 | B103: 7959.8031 | E103: 000000P105000000112 | F103: 1 | G103: 494.60616 | I103: 18R T TWO MD RG 10-36509171 | J103: 1 | K103: 2357.0205
A104: 60079850 | B104: 1298.3733 | E104: 000000P105000000113 | F104: 1 | G104: 231.84932 | I104: 18R T TWO MD RG 6 5-36509228 | J104: 1 | K104: 2357.0205
A105: 60079969 | B105: 5761.2158 | E105: 000000P105000000114 | F105: 1 | G105: 7418.8356 | I105: 18R T TWO MD RG 8-36509368 | J105: 1 | K105: 2357.0205
... A340: PV000303 | B340: 6016.2243 | E340: 000000P105000000382 | F340: 1 | G340: 1854.7089 | I340: TTN BLK 1837 NRW RG 7-25923669 | J340: 1 | K340: 316.86644
E341: 000000P105000000383 | F341: 1 | G341: 2434.2894
E342: 000000P105000000384 | F342: 1 | G342: 583.47603
E343: 000000P105000000385 | F343: 1 | G343: 2357.0205
E344: 000000P105000000386 | F344: 1 | G344: 4404.9229
E345: 000000P105000000387 | F345: 1 | G345: 2550.214
E346: 000000P105000000388 | F346: 1 | G346: 297.55993
E347: 000000P105000000390 | F347: 1 | G347: 2357.0205
E348: 000000P105000000391 | F348: 1 | G348: 401.88356
E349: 000000P105000000395 | F349: 1 | G349: 6955.137
E350: 000000P105000000396 | F350: 1 | G350: 11437.286
E351: 000000P105000000397 | F351: 1 | G351: 94241.567
E352: 000000P105000000398 | F352: 1 | G352: 4443.536
... E387: 000000P105000000436 | F387: 1 | G387: 297.55993
